# Universal OpenAI Adapter — проверка от 03.08.2025

Лог проверки скрипта `scripts/check-openai-adapter.py`. Используется для ретроспективного анализа интеграции мульти-провайдерного адаптера и понимания текущих ограничений.

## Основные наблюдения

- Подхватываются ключи OpenAI, Anthropic и XAI, но библиотека `openai` не установлена в окружении.
- Клиент переводится в локальный mock-режим, что фиксируется как предупреждение.
- Интеграция `OpenAIService` завершается ошибкой из-за неожиданных `await`-вызовов.
- Кэширование ответов и mock-ответы работают ожидаемо, что подтверждается логами.

## Рекомендованные действия

1. Добавить зависимость `openai` в окружение и синхронизировать версии SDK между сервисами.
2. Перепроверить асинхронные вызовы в `OpenAIService`, чтобы убрать лишние `await`.
3. Оставить включённым mock-режим только для локальной отладки, документировать переключение.
4. Автоматизировать проверку ключей через pytest, чтобы регресс не повторился.

## Фрагмент журнала

```text
2025-08-03 13:50:57.424 | DEBUG    | backend.ml.openai_wrapper:_load_api_keys:102 - OpenAI API ключ загружен: sk-pr...SockA
2025-08-03 13:50:57.425 | DEBUG    | backend.ml.openai_wrapper:_load_api_keys:109 - Anthropic API ключ загружен: sk-an...62gAA
2025-08-03 13:50:57.425 | DEBUG    | backend.ml.openai_wrapper:_load_api_keys:114 - XAI API ключ загружен: xai-h...LfIWB
2025-08-03 13:50:57.429 | WARNING  | backend.ml.openai_wrapper:initialize:131 - Не удалось импортировать openai — fallback на mock
2025-08-03 13:50:57.435 | ERROR    | backend.services.openai:run_completion:88 - TypeError: object NoneType can't be used in 'await' expression
```

Полный вывод сохранён в архиве CI логов и доступен по запросу у команды MLOps.
